Traceback (most recent call last):
  File "/home/codespace/.local/lib/python3.12/site-packages/jupyter_core/utils/__init__.py", line 154, in wrapped
    asyncio.get_running_loop()
RuntimeError: no running event loop

During handling of the above exception, another exception occurred:

Traceback (most recent call last):
  File "/home/codespace/.local/lib/python3.12/site-packages/jupyter_cache/executors/utils.py", line 58, in single_nb_execution
    executenb(
  File "/home/codespace/.local/lib/python3.12/site-packages/nbclient/client.py", line 1319, in execute
    return NotebookClient(nb=nb, resources=resources, km=km, **kwargs).execute()
           ^^^^^^^^^^^^^^^^^^^^^^^^^^^^^^^^^^^^^^^^^^^^^^^^^^^^^^^^^^^^^^^^^^^^^
  File "/home/codespace/.local/lib/python3.12/site-packages/jupyter_core/utils/__init__.py", line 158, in wrapped
    return loop.run_until_complete(inner)
           ^^^^^^^^^^^^^^^^^^^^^^^^^^^^^^
  File "/usr/local/python/3.12.1/lib/python3.12/asyncio/base_events.py", line 684, in run_until_complete
    return future.result()
           ^^^^^^^^^^^^^^^
  File "/home/codespace/.local/lib/python3.12/site-packages/nbclient/client.py", line 709, in async_execute
    await self.async_execute_cell(
  File "/home/codespace/.local/lib/python3.12/site-packages/nbclient/client.py", line 1062, in async_execute_cell
    await self._check_raise_for_error(cell, cell_index, exec_reply)
  File "/home/codespace/.local/lib/python3.12/site-packages/nbclient/client.py", line 918, in _check_raise_for_error
    raise CellExecutionError.from_cell_and_msg(cell, exec_reply_content)
nbclient.exceptions.CellExecutionError: An error occurred while executing the following cell:
------------------
c = Circle(Point(1,1), 2)
print(c.in_circle(Point(0,0)))
print(c.in_circle(Point(2,3)))    
------------------


[31m---------------------------------------------------------------------------[39m
[31mTypeError[39m                                 Traceback (most recent call last)
[36mCell[39m[36m [39m[32mIn[14][39m[32m, line 2[39m
[32m      1[39m c = Circle(Point([32m1[39m,[32m1[39m), [32m2[39m)
[32m----> [39m[32m2[39m [38;5;28mprint[39m([43mc[49m[43m.[49m[43min_circle[49m[43m([49m[43mPoint[49m[43m([49m[32;43m0[39;49m[43m,[49m[32;43m0[39;49m[43m)[49m[43m)[49m)
[32m      3[39m [38;5;28mprint[39m(c.in_circle(Point([32m2[39m,[32m3[39m)))    

[36mCell[39m[36m [39m[32mIn[13][39m[32m, line 12[39m, in [36mCircle.in_circle[39m[34m(self, point)[39m
[32m     11[39m [38;5;28;01mdef[39;00m[38;5;250m [39m[34min_circle[39m([38;5;28mself[39m, point):
[32m---> [39m[32m12[39m     [38;5;28;01mreturn[39;00m [38;5;28;43mself[39;49m[43m.[49m[43mcenter[49m[43m.[49m[43mdistance[49m[43m([49m[43mpoint[49m[43m)[49m[43m [49m[43m<[49m[43m [49m[38;5;28;43mself[39;49m[43m.[49m[43mradius[49m

[31mTypeError[39m: '<' not supported between instances of 'NoneType' and 'int'

