Traceback (most recent call last):
  File "/home/codespace/.local/lib/python3.12/site-packages/jupyter_core/utils/__init__.py", line 154, in wrapped
    asyncio.get_running_loop()
RuntimeError: no running event loop

During handling of the above exception, another exception occurred:

Traceback (most recent call last):
  File "/home/codespace/.local/lib/python3.12/site-packages/jupyter_cache/executors/utils.py", line 58, in single_nb_execution
    executenb(
  File "/home/codespace/.local/lib/python3.12/site-packages/nbclient/client.py", line 1319, in execute
    return NotebookClient(nb=nb, resources=resources, km=km, **kwargs).execute()
           ^^^^^^^^^^^^^^^^^^^^^^^^^^^^^^^^^^^^^^^^^^^^^^^^^^^^^^^^^^^^^^^^^^^^^
  File "/home/codespace/.local/lib/python3.12/site-packages/jupyter_core/utils/__init__.py", line 158, in wrapped
    return loop.run_until_complete(inner)
           ^^^^^^^^^^^^^^^^^^^^^^^^^^^^^^
  File "/usr/local/python/3.12.1/lib/python3.12/asyncio/base_events.py", line 684, in run_until_complete
    return future.result()
           ^^^^^^^^^^^^^^^
  File "/home/codespace/.local/lib/python3.12/site-packages/nbclient/client.py", line 709, in async_execute
    await self.async_execute_cell(
  File "/home/codespace/.local/lib/python3.12/site-packages/nbclient/client.py", line 1062, in async_execute_cell
    await self._check_raise_for_error(cell, cell_index, exec_reply)
  File "/home/codespace/.local/lib/python3.12/site-packages/nbclient/client.py", line 918, in _check_raise_for_error
    raise CellExecutionError.from_cell_and_msg(cell, exec_reply_content)
nbclient.exceptions.CellExecutionError: An error occurred while executing the following cell:
------------------
table = [ [6, 9, -18, 12, 21], 
          [5, 20, 0, 4, 16], 
          [-6, 5, -12, -6, -13]]

table_sum, table_min, table_max, sorted_table = table_statistics(table)

print("table_sum: ", table_sum, "\ntable_min: ", table_min, "\ntable_max: ", table_max, "\nsorted_table: ", sorted_table)
------------------


[31m---------------------------------------------------------------------------[39m
[31mNameError[39m                                 Traceback (most recent call last)
[36mCell[39m[36m [39m[32mIn[20][39m[32m, line 5[39m
[32m      1[39m table = [ [[32m6[39m, [32m9[39m, -[32m18[39m, [32m12[39m, [32m21[39m], 
[32m      2[39m           [[32m5[39m, [32m20[39m, [32m0[39m, [32m4[39m, [32m16[39m], 
[32m      3[39m           [-[32m6[39m, [32m5[39m, -[32m12[39m, -[32m6[39m, -[32m13[39m]]
[32m----> [39m[32m5[39m table_sum, table_min, table_max, sorted_table = [43mtable_statistics[49m[43m([49m[43mtable[49m[43m)[49m
[32m      7[39m [38;5;28mprint[39m([33m"[39m[33mtable_sum: [39m[33m"[39m, table_sum, [33m"[39m[38;5;130;01m\n[39;00m[33mtable_min: [39m[33m"[39m, table_min, [33m"[39m[38;5;130;01m\n[39;00m[33mtable_max: [39m[33m"[39m, table_max, [33m"[39m[38;5;130;01m\n[39;00m[33msorted_table: [39m[33m"[39m, sorted_table)

[36mCell[39m[36m [39m[32mIn[19][39m[32m, line 4[39m, in [36mtable_statistics[39m[34m(table)[39m
[32m      1[39m [38;5;28;01mdef[39;00m[38;5;250m [39m[34mtable_statistics[39m(table):
[32m      2[39m     [38;5;66;03m# Write your code here[39;00m
[32m----> [39m[32m4[39m     [38;5;28;01mreturn[39;00m [43mtable_sum[49m, table_min, table_max, sorted_table

[31mNameError[39m: name 'table_sum' is not defined

